<?xml version="1.0" ?>
<!-- =================================================================================== -->
<!-- |    This document was autogenerated by xacro from comar_base.xacro               | -->
<!-- |    EDITING THIS FILE BY HAND IS NOT RECOMMENDED                                 | -->
<!-- =================================================================================== -->
<!--
  COMAR ROBOT ASELSAN 

  COMMENTED PARTS ARE USED FOR GAZEBOSIM
-->
<robot name="comar">
  <!--[Ns/m] -->
  <!-- [kg] -->
  <!-- 
   <xacro:property name="Body_Length" value="0.487" /> 
   <xacro:property name="Body_Width" value="0.287" /> 
   <xacro:property name="Body_Heigth" value="0.214" />

   <xacro:property name="ABAD_LinkLength" value="0.08374" /> 
   <xacro:property name="Hip_LinkLength" value="0.2" /> 
   <xacro:property name="Knee_LinkLength" value="0.2" /> 
   <xacro:property name="ABAD_XOffset" value="0.056" /> 
   <xacro:property name="Knee_YOffset" value="0.0" /> 
 -->
  <!--[N] -->
  <link name="comar/base_link"> </link>
  <joint name="comar/base_joint" type="fixed">
    <origin rpy="0 0 0" xyz="0 0 0"/>
    <parent link="comar/base_link"/>
    <child link="comar/base_link_inertia"/>
  </joint>
  <link name="comar/base_link_inertia">
    <inertial>
      <mass value="18.596"/>
      <!-- [kg] -->
      <origin rpy="0 0 0" xyz="0 0 0"/>
      <inertia ixx="144005e-6" ixy="254013e-6" ixz="-1667.22e-6" iyy="380679e-6" iyz="1300.96e-6" izz="447682e-6"/>
    </inertial>
    <visual>
      <origin rpy="0 0 0" xyz="0 0 0"/>
      <geometry>
        <mesh filename="../meshes/ROBOT_GOVDE.stl"/>
      </geometry>
    </visual>
    <collision>
      <origin rpy="0 0 0" xyz="0 0 0"/>
      <geometry>
        <mesh filename="../meshes/ROBOT_GOVDE.stl"/>
      </geometry>
    </collision>
  </link>
  <!-- ================================================_LEG 1 - FR_======================================================== -->
  <joint name="comar/abad_1_joint" type="revolute">
    <limit effort="1000" lower="-3.1415" upper="3.1415" velocity="1000"/>
    <dynamics damping="0.03" friction="0.05"/>
    <origin rpy="0 0 0" xyz="222.50e-3 -65.50e-3 0"/>
    <axis xyz="1 0 0"/>
    <parent link="comar/base_link"/>
    <child link="comar/abad_1"/>
  </joint>
  <link name="comar/abad_1">
    <inertial>
      <origin xyz="-0.011366 -0.007729 0.0048783"/>
      <mass value="0.8602"/>
      <!-- [kg] -->
      <inertia ixx="590.764e-06" ixy="-4.1943e-06" ixz="-0.6819e-06" iyy="1220.42e-06" iyz="-1.6663e-06" izz="938.409e-06"/>
    </inertial>
    <visual>
      <origin rpy="0 0 0" xyz="0 0 0"/>
      <geometry>
        <mesh filename="../meshes/ROBOT_ABDUCTION_FR.stl"/>
      </geometry>
    </visual>
    <collision>
      <origin rpy="0 0 0" xyz="0 0 0"/>
      <geometry>
        <mesh filename="../meshes/ROBOT_ABDUCTION_FR.stl"/>
      </geometry>
    </collision>
  </link>
  <joint name="comar/hip_1_joint" type="revolute">
    <limit effort="1000" lower="-3.1415" upper="3.1415" velocity="1000"/>
    <dynamics damping="0.03" friction="0.05"/>
    <origin rpy="0 0 0" xyz="0.07675 -0.0155 0 "/>
    <axis xyz="0 1 0"/>
    <parent link="comar/abad_1"/>
    <child link="comar/hip_1"/>
  </joint>
  <link name="comar/hip_1">
    <inertial>
      <origin xyz="-0.00309 -0.05402 -0.02642"/>
      <mass value="1.3625"/>
      <inertia ixx="5973.76e-06" ixy="120.436e-06" ixz="399.581e-06" iyy="5820.53e-06" iyz="875.295e-06" izz="1518.4e-06"/>
    </inertial>
    <visual>
      <origin rpy="0 0 0" xyz="0 0 0"/>
      <geometry>
        <mesh filename="../meshes/ROBOT_HIP_R.stl"/>
      </geometry>
    </visual>
    <collision>
      <origin rpy="0 0 0" xyz="0 0 0"/>
      <geometry>
        <mesh filename="../meshes/ROBOT_HIP_R.stl"/>
      </geometry>
    </collision>
  </link>
  <joint name="comar/knee_1_joint" type="revolute">
    <limit effort="0" lower="-3.1415" upper="3.1415" velocity="1000"/>
    <dynamics damping="0.03" friction="0.05"/>
    <origin rpy="0 0 0" xyz="0 -0.08024 -0.2 "/>
    <axis xyz="0 1 0"/>
    <parent link="comar/hip_1"/>
    <child link="comar/knee_1"/>
  </joint>
  <link name="comar/knee_1">
    <inertial>
      <origin xyz="0.00708 0.0009 0.13802"/>
      <mass value="1e-12"/>
      <inertia ixx="1555.11e-06" ixy="0.0923e-06" ixz="-4.0365e-06" iyy="1573.95e-06" iyz="-9.4347e-06" izz="56.1384e-06"/>
    </inertial>
    <visual>
      <origin rpy="0 0 0" xyz="0 0 0"/>
      <geometry>
        <mesh filename="../meshes/ROBOT_KNEE.stl"/>
      </geometry>
    </visual>
    <collision>
      <origin rpy="0 0 0" xyz="0 0 0"/>
      <geometry>
        <mesh filename="../meshes/ROBOT_KNEE.stl"/>
      </geometry>
    </collision>
  </link>
  <joint name="comar/foot_1_joint" type="fixed">
    <origin rpy="0 0 0" xyz="0 0 -0.199696 "/>
    <parent link="comar/knee_1"/>
    <child link="comar/foot_1"/>
  </joint>
  <link name="comar/foot_1">
    <inertial>
      <origin xyz="0.0 0.0 0.0"/>
      <mass value="0.05"/>
      <inertia ixx="0.000005" ixy="0.000005" ixz="0.000005" iyy="0.000005" iyz="0.000005" izz="0.000005"/>
    </inertial>
    <visual>
      <origin rpy="0 0 0" xyz="0 0 0"/>
      <geometry>
        <mesh filename="../meshes/ROBOT_FOOT.stl"/>
      </geometry>
    </visual>
    <collision>
      <origin rpy="0 0 0" xyz="0 0 0"/>
      <geometry>
        <mesh filename="../meshes/ROBOT_FOOT.stl"/>
      </geometry>
    </collision>
  </link>
  <!-- ================================================_LEG 2 - FL_======================================================== -->
  <joint name="comar/abad_2_joint" type="revolute">
    <limit effort="1000" lower="-3.1415" upper="3.1415" velocity="1000"/>
    <dynamics damping="0.03" friction="0.05"/>
    <origin rpy="0 0 0" xyz="222.50e-3 65.50e-3 0"/>
    <axis xyz="1 0 0"/>
    <parent link="comar/base_link"/>
    <child link="comar/abad_2"/>
  </joint>
  <link name="comar/abad_2">
    <inertial>
      <origin xyz="-0.011366 0.007729 0.0048783"/>
      <mass value="0.8602"/>
      <!-- [kg] -->
      <inertia ixx="1220.42e-06" ixy="-4.428e-06" ixz="-0.8715e-06" iyy="693.402e-06" iyz="158.578e-06" izz="835.772e-06"/>
    </inertial>
    <visual>
      <origin rpy="0 0 0" xyz="0 0 0"/>
      <geometry>
        <mesh filename="../meshes/ROBOT_ABDUCTION_FL.stl"/>
      </geometry>
    </visual>
    <collision>
      <origin rpy="0 0 0" xyz="0 0 0"/>
      <geometry>
        <mesh filename="../meshes/ROBOT_ABDUCTION_FL.stl"/>
      </geometry>
    </collision>
  </link>
  <joint name="comar/hip_2_joint" type="revolute">
    <limit effort="1000" lower="-3.1415" upper="3.1415" velocity="1000"/>
    <dynamics damping="0.03" friction="0.05"/>
    <origin rpy="0 0 0" xyz="0.07675 0.0155 0 "/>
    <axis xyz="0 1 0"/>
    <parent link="comar/abad_2"/>
    <child link="comar/hip_2"/>
  </joint>
  <link name="comar/hip_2">
    <inertial>
      <origin xyz="-0.00309 0.05402 -0.02642"/>
      <mass value="1.3625"/>
      <inertia ixx="5973.75e-06" ixy="-120.436e-06" ixz="399.58e-06" iyy="5820.52e-06" iyz="-875.292e-06" izz="1518.4e-06"/>
    </inertial>
    <visual>
      <origin rpy="0 0 0" xyz="0 0 0"/>
      <geometry>
        <mesh filename="../meshes/ROBOT_HIP_L.stl"/>
      </geometry>
    </visual>
    <collision>
      <origin rpy="0 0 0" xyz="0 0 0"/>
      <geometry>
        <mesh filename="../meshes/ROBOT_HIP_L.stl"/>
      </geometry>
    </collision>
  </link>
  <joint name="comar/knee_2_joint" type="revolute">
    <limit effort="0" lower="-3.1415" upper="3.1415" velocity="1000"/>
    <dynamics damping="0.03" friction="0.05"/>
    <origin rpy="0 0 0" xyz="0 0.08024 -0.2 "/>
    <axis xyz="0 1 0"/>
    <parent link="comar/hip_2"/>
    <child link="comar/knee_2"/>
  </joint>
  <link name="comar/knee_2">
    <inertial>
      <origin xyz="0.00708 -0.0009 0.13802"/>
      <mass value="1e-12"/>
      <inertia ixx="1555.76e-06" ixy="0.115e-06" ixz="-4.2593e-06" iyy="1574.68e-06" iyz="-9.6089e-06" izz="56.2211e-06"/>
    </inertial>
    <visual>
      <origin rpy="0 0 0" xyz="0 0 0"/>
      <geometry>
        <mesh filename="../meshes/ROBOT_KNEE.stl"/>
      </geometry>
    </visual>
    <collision>
      <origin rpy="0 0 0" xyz="0 0 0"/>
      <geometry>
        <mesh filename="../meshes/ROBOT_KNEE.stl"/>
      </geometry>
    </collision>
  </link>
  <!-- <joint name="comar/foot_2_joint" type="fixed">
    <origin rpy="0 0 0" xyz="0 0 -0.199696 "/>
    <parent link="comar/knee_2"/>
    <child link="comar/foot_2"/>
  </joint>
  <link name="comar/foot_2">
    <inertial>
      <origin xyz="0.0 0.0 0.0"/>
      <mass value="0.05"/>
      <inertia ixx="0.000005" ixy="0.000005" ixz="0.000005" iyy="0.000005" iyz="0.000005" izz="0.000005"/>
    </inertial>
    <visual>
      <origin rpy="0 0 0" xyz="0 0 0"/>
      <geometry>
        <mesh filename="../meshes/ROBOT_FOOT.stl"/>
      </geometry>
    </visual>
    <collision>
      <origin rpy="0 0 0" xyz="0 0 0"/>
      <geometry>
        <mesh filename="../meshes/ROBOT_FOOT.stl"/>
      </geometry>
    </collision>
  </link> -->
  <joint name="FL_foot_fixed" type="fixed" dont_collapse="true">
    <origin rpy="0 0 0" xyz="0 0 -0.213"/>
    <parent link="comar/foot_2"/>
    <child link="FL_foot"/>
  </joint>
  <link name="FL_foot">
    <visual>
      <origin rpy="0 0 0" xyz="0 0 0"/>
      <geometry>
        <sphere radius="0.01"/>
      </geometry>
      <material name="black"/>
    </visual>
    <collision>
      <origin rpy="0 0 0" xyz="0 0 0"/>
      <geometry>
        <sphere radius="0.02"/>
      </geometry>
    </collision>
    <inertial>
      <mass value="0.06"/>
      <inertia ixx="9.6e-06" ixy="0.0" ixz="0.0" iyy="9.6e-06" iyz="0.0" izz="9.6e-06"/>
    </inertial>
  </link>
  <!-- ================================================_LEG 3 - HR_======================================================== -->
  <joint name="comar/abad_3_joint" type="revolute">
    <limit effort="1000" lower="-3.1415" upper="3.1415" velocity="1000"/>
    <dynamics damping="0.03" friction="0.05"/>
    <origin rpy="0 0 0" xyz="-222.50e-3 -65.50e-3 0"/>
    <axis xyz="1 0 0"/>
    <parent link="comar/base_link"/>
    <child link="comar/abad_3"/>
  </joint>
  <link name="comar/abad_3">
    <inertial>
      <origin xyz="0.011366 -0.007729 0.0048783"/>
      <mass value="0.8602"/>
      <!-- [kg] -->
      <inertia ixx="590.764e-06" ixy="4.1943e-06" ixz="-0.6819e-06" iyy="1220.42e-06" iyz="1.6663e-06" izz="938.409e-06"/>
    </inertial>
    <visual>
      <origin rpy="0 0 0" xyz="0 0 0"/>
      <geometry>
        <mesh filename="../meshes/ROBOT_ABDUCTION_HR.stl"/>
      </geometry>
    </visual>
    <collision>
      <origin rpy="0 0 0" xyz="0 0 0"/>
      <geometry>
        <mesh filename="../meshes/ROBOT_ABDUCTION_HR.stl"/>
      </geometry>
    </collision>
  </link>
  <joint name="comar/hip_3_joint" type="revolute">
    <limit effort="1000" lower="-3.1415" upper="3.1415" velocity="1000"/>
    <dynamics damping="0.03" friction="0.05"/>
    <origin rpy="0 0 0" xyz="-0.07675 -0.0155 0 "/>
    <axis xyz="0 1 0"/>
    <parent link="comar/abad_3"/>
    <child link="comar/hip_3"/>
  </joint>
  <link name="comar/hip_3">
    <inertial>
      <origin xyz="-0.00309 -0.05402 -0.02642"/>
      <mass value="1.3625"/>
      <inertia ixx="5973.76e-06" ixy="120.436e-06" ixz="399.581e-06" iyy="5820.53e-06" iyz="875.295e-06" izz="1518.4e-06"/>
    </inertial>
    <visual>
      <origin rpy="0 0 0" xyz="0 0 0"/>
      <geometry>
        <mesh filename="../meshes/ROBOT_HIP_R.stl"/>
      </geometry>
    </visual>
    <collision>
      <origin rpy="0 0 0" xyz="0 0 0"/>
      <geometry>
        <mesh filename="../meshes/ROBOT_HIP_R.stl"/>
      </geometry>
    </collision>
  </link>
  <joint name="comar/knee_3_joint" type="revolute">
    <limit effort="0" lower="-3.1415" upper="3.1415" velocity="1000"/>
    <dynamics damping="0.03" friction="0.05"/>
    <origin rpy="0 0 0" xyz="0 -0.08024 -0.2 "/>
    <axis xyz="0 1 0"/>
    <parent link="comar/hip_3"/>
    <child link="comar/knee_3"/>
  </joint>
  <link name="comar/knee_3">
    <inertial>
      <origin xyz="0.00708 -0.0009 0.13802"/>
      <mass value="1e-12"/>
      <inertia ixx="1555.11e-06" ixy="0.0923e-06" ixz="-4.0365e-06" iyy="1573.95e-06" iyz="-9.4347e-06" izz="56.1384e-06"/>
    </inertial>
    <visual>
      <origin rpy="0 0 0" xyz="0 0 0"/>
      <geometry>
        <mesh filename="../meshes/ROBOT_KNEE.stl"/>
      </geometry>
    </visual>
    <collision>
      <origin rpy="0 0 0" xyz="0 0 0"/>
      <geometry>
        <mesh filename="../meshes/ROBOT_KNEE.stl"/>
      </geometry>
    </collision>
  </link>
  <joint name="comar/foot_3_joint" type="fixed">
    <origin rpy="0 0 0" xyz="0 0 -0.199696 "/>
    <parent link="comar/knee_3"/>
    <child link="comar/foot_3"/>
  </joint>
  <link name="comar/foot_3">
    <inertial>
      <origin xyz="0.0 0.0 0.0"/>
      <mass value="0.05"/>
      <inertia ixx="0.000005" ixy="0.000005" ixz="0.000005" iyy="0.000005" iyz="0.000005" izz="0.000005"/>
    </inertial>
    <visual>
      <origin rpy="0 0 0" xyz="0 0 0"/>
      <geometry>
        <mesh filename="../meshes/ROBOT_FOOT.stl"/>
      </geometry>
    </visual>
    <collision>
      <origin rpy="0 0 0" xyz="0 0 0"/>
      <geometry>
        <mesh filename="../meshes/ROBOT_FOOT.stl"/>
      </geometry>
    </collision>
  </link>
  <!-- ================================================_LEG 4 - HL_======================================================== -->
  <joint name="comar/abad_4_joint" type="revolute">
    <limit effort="1000" lower="-3.1415" upper="3.1415" velocity="1000"/>
    <dynamics damping="0.03" friction="0.05"/>
    <origin rpy="0 0 0" xyz="-222.50e-3 65.50e-3 0"/>
    <axis xyz="1 0 0"/>
    <parent link="comar/base_link"/>
    <child link="comar/abad_4"/>
  </joint>
  <link name="comar/abad_4">
    <inertial>
      <origin xyz="0.011366 0.007729 0.0048783"/>
      <mass value="0.8602"/>
      <!-- [kg] -->
      <inertia ixx="590.766e-06" ixy="-4.1941e-06" ixz="-0.6823e-06" iyy="1220.42e-06" iyz="-1.6661e-06" izz="938.409e-06"/>
    </inertial>
    <visual>
      <origin rpy="0 0 0" xyz="0 0 0"/>
      <geometry>
        <mesh filename="../meshes/ROBOT_ABDUCTION_HL.stl"/>
      </geometry>
    </visual>
    <collision>
      <origin rpy="0 0 0" xyz="0 0 0"/>
      <geometry>
        <mesh filename="../meshes/ROBOT_ABDUCTION_HL.stl"/>
      </geometry>
    </collision>
  </link>
  <joint name="comar/hip_4_joint" type="revolute">
    <limit effort="1000" lower="-3.1415" upper="3.1415" velocity="1000"/>
    <dynamics damping="0.03" friction="0.05"/>
    <origin rpy="0 0 0" xyz="-0.07675 0.0155 0 "/>
    <axis xyz="0 1 0"/>
    <parent link="comar/abad_4"/>
    <child link="comar/hip_4"/>
  </joint>
  <link name="comar/hip_4">
    <inertial>
      <origin xyz="-0.00309 0.05402 -0.02642"/>
      <mass value="1.3625"/>
      <inertia ixx="5973.75e-06" ixy="-120.436e-06" ixz="399.58e-06" iyy="5820.52e-06" iyz="-875.292e-06" izz="1518.4e-06"/>
    </inertial>
    <visual>
      <origin rpy="0 0 0" xyz="0 0 0"/>
      <geometry>
        <mesh filename="../meshes/ROBOT_HIP_L.stl"/>
      </geometry>
    </visual>
    <collision>
      <origin rpy="0 0 0" xyz="0 0 0"/>
      <geometry>
        <mesh filename="../meshes/ROBOT_HIP_L.stl"/>
      </geometry>
    </collision>
  </link>
  <joint name="comar/knee_4_joint" type="revolute">
    <limit effort="0" lower="-3.1415" upper="3.1415" velocity="1000"/>
    <dynamics damping="0.03" friction="0.05"/>
    <origin rpy="0 0 0" xyz="0 0.08024 -0.2 "/>
    <axis xyz="0 1 0"/>
    <parent link="comar/hip_4"/>
    <child link="comar/knee_4"/>
  </joint>
  <link name="comar/knee_4">
    <inertial>
      <origin xyz="0.00708 0.0009 0.13802"/>
      <mass value="1e-12"/>
      <inertia ixx="1555.76e-06" ixy="0.115e-06" ixz="4.2593e-06" iyy="1574.68e-06" iyz="9.6089e-06" izz="56.2211e-06"/>
    </inertial>
    <visual>
      <origin rpy="0 0 0" xyz="0 0 0"/>
      <geometry>
        <mesh filename="../meshes/ROBOT_KNEE.stl"/>
      </geometry>
    </visual>
    <collision>
      <origin rpy="0 0 0" xyz="0 0 0"/>
      <geometry>
        <mesh filename="../meshes/ROBOT_KNEE.stl"/>
      </geometry>
    </collision>
  </link>
  <joint name="comar/foot_4_joint" type="fixed">
    <origin rpy="0 0 0" xyz="0 0 -0.199696 "/>
    <parent link="comar/knee_4"/>
    <child link="comar/foot_4"/>
  </joint>
  <link name="comar/foot_4">
    <inertial>
      <origin xyz="0.0 0.0 0.0"/>
      <mass value="0.05"/>
      <inertia ixx="0.000005" ixy="0.000005" ixz="0.000005" iyy="0.000005" iyz="0.000005" izz="0.000005"/>
    </inertial>
    <visual>
      <origin rpy="0 0 0" xyz="0 0 0"/>
      <geometry>
        <mesh filename="../meshes/ROBOT_FOOT.stl"/>
      </geometry>
    </visual>
    <collision>
      <origin rpy="0 0 0" xyz="0 0 0"/>
      <geometry>
        <mesh filename="../meshes/ROBOT_FOOT.stl"/>
      </geometry>
    </collision>
  </link>
  <!-- Instantiate a controller. -->
  <!-- <xacro:controller_plugin_macro namespace="${namespace}" imu_sub_topic="imu" /> -->
  <!-- <xacro:if value="$(arg enable_mavlink_interface)">

    <xacro:default_mavlink_interface namespace="${namespace}" imu_sub_topic="imu" rotor_count="4" />
  </xacro:if> -->
  <!-- Mount an ADIS16448 IMU. -->
  <!-- <xacro:default_imu namespace="${namespace}" parent_link="${namespace}/base_link" /> -->
  <!-- Mount a GPS. -->
  <!-- <xacro:default_gps namespace="${namespace}" parent_link="${namespace}/base_link" /> -->
  <!-- <xacro:if value="$(arg enable_ground_truth)">
    <xacro:ground_truth_imu_and_odometry namespace="${namespace}" parent_link="${namespace}/base_link" />
  </xacro:if> -->
  <!-- 
  <xacro:if value="$(arg enable_logging)">
    <xacro:bag_plugin_macro
      namespace="${namespace}"
      bag_file="$(arg log_file)"
      rotor_velocity_slowdown_sim="${rotor_velocity_slowdown_sim}"
      wait_to_record_bag="$(arg wait_to_record_bag)" />
  </xacro:if> -->
</robot>
